<?xml version="1.0" ?>
<robot name="slambot" xmlns:xacro="http://ros.org/wiki/xacro">
  <!-- <xacro:include filename="$(find slambot_description)/urdf/common_properties.xacro"/> -->

  <material name="grey">
    <color rgba="0.5 0.5 0.5 1.0"/>
  </material>
  <material name="dark_grey">
    <color rgba="0.3 0.3 0.3 1.0"/>
  </material>
  <material name="light_grey">
    <color rgba="0.9 0.9 0.9 1.0"/>
  </material>
  <material name="green">
    <color rgba="0.0 0.8 0.0 1.0"/>
  </material>
  <material name="pla">
    <color rgba="0.9 0.9 0.85 1.0"/>
  </material>


  <link name="base_link">
    <visual>
      <origin xyz="0.0 0 0.0" rpy="0 0 1.57"/>
      <geometry>
        <mesh filename="package://slambot_description/meshes/frame.stl" scale="0.001 0.001 0.001"/>
      </geometry>
      <material name="pla"/>
    </visual>

    <collision>
      <origin xyz="-0.025 0 0.065" rpy="0 0 0"/>
      <geometry>
        <box size="0.130 0.130 0.110"/>
      </geometry>
    </collision>

  </link>

  <joint name="wheel_left_joint" type="continuous">
    <parent link="base_link"/>
    <child link="wheel_left_link"/>
    <origin xyz="0.0 0.07 0.035" rpy="-1.57 0 0"/>
    <axis xyz="0 0 1"/>
  </joint>

  <link name="wheel_left_link">
    <visual>
      <origin xyz="0 0 0" rpy="0 3.14 0"/>
      <geometry>
        <mesh filename="package://slambot_description/meshes/wheel.stl" scale="0.001 0.001 0.001"/>
      </geometry>
      <material name="green"/>
    </visual>

    <collision>
      <origin xyz="0 0 0" rpy="0 0 0"/>
      <geometry>
        <cylinder length="0.012" radius="0.035"/>
      </geometry>
    </collision>

    <inertial>
      <origin xyz="0 0 0" />
      <mass value="2.8498940e-02" />
      <inertia ixx="1.1175580e-05" ixy="-4.2369783e-11" ixz="-5.9381719e-09"
               iyy="1.1192413e-05" iyz="-1.4400107e-11"
               izz="2.0712558e-05" />
      </inertial>
  </link>

  <joint name="wheel_right_joint" type="continuous">
    <parent link="base_link"/>
    <child link="wheel_right_link"/>
    <origin xyz="0.0 -0.07 0.035" rpy="-1.57 0 0"/>
    <axis xyz="0 0 1"/>
  </joint>

  <link name="wheel_right_link">
    <visual>
      <origin xyz="0 0 0" rpy="0 0 0"/>
      <geometry>
        <mesh filename="package://slambot_description/meshes/wheel.stl" scale="0.001 0.001 0.001"/>
      </geometry>
      <material name="green"/>
    </visual>

    <collision>
      <origin xyz="0 0 0" rpy="0 0 0"/>
      <geometry>
        <cylinder length="0.012" radius="0.035"/>
      </geometry>
    </collision>

    <inertial>
      <origin xyz="0 0 0" />
      <mass value="2.8498940e-02" />
      <inertia ixx="1.1175580e-05" ixy="-4.2369783e-11" ixz="-5.9381719e-09"
               iyy="1.1192413e-05" iyz="-1.4400107e-11"
               izz="2.0712558e-05" />
      </inertial>
  </link>

  <joint name="caster_back_joint" type="fixed">
    <parent link="base_link"/>
    <child link="caster_back_link"/>
    <origin xyz="-0.078 0 0.005" rpy="-1.57 0 0"/>
  </joint>

  <link name="caster_back_link">
    <collision>
      <origin xyz="0 0 0" rpy="0 0 0"/>
      <geometry>
        <box size="0.030 0.009 0.022"/>
      </geometry>
    </collision>

    <inertial>
      <origin xyz="0 0 0" />
      <mass value="0.005" />
      <inertia ixx="0.001" ixy="0.0" ixz="0.0"
               iyy="0.001" iyz="0.0"
               izz="0.001" />
    </inertial>
  </link>

  <joint name="imu_joint" type="fixed">
    <parent link="base_link"/>
    <child link="imu_link"/>
    <origin xyz="-0.032 0 0.068" rpy="0 0 0"/>
  </joint>

  <link name="imu_link"/>

  <joint name="lidar_joint" type="fixed">
    <parent link="base_link"/>
    <child link="lidar_link"/>
    <origin xyz="-0.035 0 0.14" rpy="0 0 3.1415"/>
  </joint>

  <link name="lidar_link">
    <visual>
      <origin xyz="0 0 0.0" rpy="0 0 -1.57"/>
      <geometry>
        <mesh filename="package://slambot_description/meshes/lidar.stl" scale="0.001 0.001 0.001"/>
      </geometry>
      <material name="dark_grey"/>
    </visual>

    <collision>
      <origin xyz="0.01 0 -0.0065" rpy="0 0 0"/>
      <geometry>
        <cylinder length="0.0316" radius="0.065"/>
      </geometry>
    </collision>

    <inertial>
      <mass value="0.114" />
      <origin xyz="0 0 0" />
      <inertia ixx="0.001" ixy="0.0" ixz="0.0"
               iyy="0.001" iyz="0.0"
               izz="0.001" />
    </inertial>
  </link>

  <joint name="camera_joint" type="fixed">
    <parent link="base_link"/>
    <child link="camera_link"/>
    <origin xyz="0.039 0 0.123" rpy="0 0 0"/>
  </joint>

  <link name="camera_link">
    <visual>
      <origin xyz="0 0 0.0" rpy="0 0 -1.57"/>
      <geometry>
        <mesh filename="package://slambot_description/meshes/camera.stl" scale="0.001 0.001 0.001"/>
      </geometry>
      <material name="dark_grey"/>
    </visual>

    <collision>
      <origin xyz="0 0 -0.005" rpy="0 0 0"/>
      <geometry>
        <box size="0.01 0.025 0.025"/>
      </geometry>
    </collision>
    <collision>
      <origin xyz="0.013 0 0" rpy="0 1.57 0"/>
      <geometry>
        <cylinder length="0.015" radius="0.0075"/>
      </geometry>
    </collision>

  </link>

</robot>
